Workbook

Sheet Guide
A1: SmartFlow UAT encoding workbook (ISO/IEC 25010)
A2: Prepared 26 October 2026 for the 12 November 2026 defense. Blank template: it contains no scores.
A4: Where to type
A5: Yellow cells with blue text | B5: Type here: Responses, Feedback, the scale on Summary, and the method choice on Summary.
A6: Grey or white cells | B6: Formulas. Do not overwrite them.
A7: Steps
A8: 1 | B8: After each respondent finishes the questionnaire, add one row on Responses (Resp ID, role, office, device, session type, date, then the 27 scores).
A9: 2 | B9: Copy the open answers (Part C) to Feedback under the same Resp ID.
A10: 3 | B10: Check the Check column on Responses. 'Incomplete' means some items are blank; confirm with the paper or form before leaving it.
A11: 4 | B11: Read Summary: Table 5.2 (respondents), Table 5.4 (WM and interpretation per characteristic and overall). Item_Results has every item's mean.
A12: 5 | B12: Copy the numbers into docs/thesis/chapter-5-results-and-discussion.md (Tables 5.2 and 5.4). Choose the overall method on Summary and state it in Chapter 5; the sentence in Summary row 49 can be pasted.
A13: Rules
A14: No invented scores | B14: Leave a cell blank until the respondent answered. Blank cells are ignored, never treated as zero.
A15: Who counts | B15: A respondent is counted when at least one item is answered. The instrument suggests about 4 to 7 respondents for a small LGU pilot, if the adviser agrees.
A16: Honest session wording | B16: If the session was a remote demonstration, write that in Chapter 4 and 5 (see docs/thesis/appendix-iso-25010-survey.md). Do not write that the system is deployed or in daily use unless it is.
A17: Sources
A18: Items and instructions | B18: docs/thesis/appendix-iso-25010-survey.md (27 items, 5-point Likert, encoding method).
A19: Interpretation scale | B19: docs/thesis/chapter-5-results-and-discussion.md, Table 5.3 (scale approved by the research adviser).
A21: Example of one respondent row (EXAMPLE ONLY: not data, not counted, do not copy the scores)
A22: Field | B22: Example value and format
A23: Resp ID | B23: R01 (already filled; one row per respondent)
A24: Role | B24: Clerk / staff (pick from the list)
A25: Office | B25: ACC (pick from the list)
A26: Device used | B26: Web (browser) (pick from the list)
A27: Session type | B27: Remote call (pick from the list)
A28: Date (yyyy-mm-dd) | B28: 2026-11-03
A29: FS1 to PO3 | B29: A whole number from 1 to 5 for each item, for example 4. Blank = not answered.

Sheet Responses
A1: SmartFlow UAT: respondent answers (ISO/IEC 25010)
A2: Type each respondent's answers in the yellow cells. 5 = Strongly Agree, 4 = Agree, 3 = Uncertain, 2 = Disagree, 1 = Strongly Disagree. Leave a cell blank when the respondent did not answer; never estimate a score.
A3: Grey cells are formulas. A respondent is counted once at least one item is answered.
G4: Functional suitability | K4: Performance efficiency | N4: Compatibility | Q4: Usability | U4: Reliability | X4: Security | AB4: Maintainability | AE4: Portability
A5: Resp ID | B5: Role | C5: Office | D5: Device used | E5: Session type | F5: Date (yyyy-mm-dd) | G5: FS1 | H5: FS2 | I5: FS3 | J5: FS4 | K5: PE1 | L5: PE2 | M5: PE3 | N5: CO1 | O5: CO2 | P5: CO3 | Q5: US1 | R5: US2 | S5: US3 | T5: US4 | U5: RE1 | V5: RE2 | W5: RE3 | X5: SE1 | Y5: SE2 | Z5: SE3 | AA5: SE4 | AB5: MA1 | AC5: MA2 | AD5: MA3 | AE5: PO1 | AF5: PO2 | AG5: PO3 | AH5: Items answered | AI5: Check
A6: R01 | AH6: =COUNT(G6:AG6) | AI6: =IF(AH6=0,"",IF(AH6=27,"OK","Incomplete: "&(27-AH6)&" blank"))
A7: R02 | AH7: =COUNT(G7:AG7) | AI7: =IF(AH7=0,"",IF(AH7=27,"OK","Incomplete: "&(27-AH7)&" blank"))
A8: R03 | AH8: =COUNT(G8:AG8) | AI8: =IF(AH8=0,"",IF(AH8=27,"OK","Incomplete: "&(27-AH8)&" blank"))
A9: R04 | AH9: =COUNT(G9:AG9) | AI9: =IF(AH9=0,"",IF(AH9=27,"OK","Incomplete: "&(27-AH9)&" blank"))
A10: R05 | AH10: =COUNT(G10:AG10) | AI10: =IF(AH10=0,"",IF(AH10=27,"OK","Incomplete: "&(27-AH10)&" blank"))
A11: R06 | AH11: =COUNT(G11:AG11) | AI11: =IF(AH11=0,"",IF(AH11=27,"OK","Incomplete: "&(27-AH11)&" blank"))
A12: R07 | AH12: =COUNT(G12:AG12) | AI12: =IF(AH12=0,"",IF(AH12=27,"OK","Incomplete: "&(27-AH12)&" blank"))
A13: R08 | AH13: =COUNT(G13:AG13) | AI13: =IF(AH13=0,"",IF(AH13=27,"OK","Incomplete: "&(27-AH13)&" blank"))
A14: R09 | AH14: =COUNT(G14:AG14) | AI14: =IF(AH14=0,"",IF(AH14=27,"OK","Incomplete: "&(27-AH14)&" blank"))
A15: R10 | AH15: =COUNT(G15:AG15) | AI15: =IF(AH15=0,"",IF(AH15=27,"OK","Incomplete: "&(27-AH15)&" blank"))
A16: R11 | AH16: =COUNT(G16:AG16) | AI16: =IF(AH16=0,"",IF(AH16=27,"OK","Incomplete: "&(27-AH16)&" blank"))
A17: R12 | AH17: =COUNT(G17:AG17) | AI17: =IF(AH17=0,"",IF(AH17=27,"OK","Incomplete: "&(27-AH17)&" blank"))
... A35: R30 | AH35: =COUNT(G35:AG35) | AI35: =IF(AH35=0,"",IF(AH35=27,"OK","Incomplete: "&(27-AH35)&" blank"))

Sheet Feedback
A1: SmartFlow UAT: open feedback (Part C of the questionnaire)
A2: Type each respondent's own words. Use the same Resp ID as on the Responses sheet.
A4: Resp ID | B4: What did you like most? | C4: What was confusing or hard? | D4: What should be improved before wider use? | E4: Recommend for pilot use? | F4: Why?
A5: R01
A6: R02
A7: R03
A8: R04
A9: R05
A10: R06
A11: R07
A12: R08
A13: R09
A14: R10
A15: R11
A16: R12
... A34: R30

Sheet Summary
A1: SmartFlow UAT: summary for Chapter 5
A2: All cells on this sheet are formulas except the two yellow ones. Values appear once answers are typed on Responses.
A4: Table 5.2: Respondents
A5: Role | B5: Respondents (n)
A6: Municipal Accountant / admin | B6: =COUNTIFS(Responses!$B$6:$B$35,A6,Responses!$AH$6:$AH$35,">0")
A7: Department head | B7: =COUNTIFS(Responses!$B$6:$B$35,A7,Responses!$AH$6:$AH$35,">0")
A8: Clerk / staff | B8: =COUNTIFS(Responses!$B$6:$B$35,A8,Responses!$AH$6:$AH$35,">0")
A9: Other | B9: =COUNTIFS(Responses!$B$6:$B$35,A9,Responses!$AH$6:$AH$35,">0")
A10: Role not selected | B10: =B11-SUM(B6:B9)
A11: Total | B11: =COUNTIF(Responses!$AH$6:$AH$35,">0")
A13: Respondents by office
A14: Office | B14: Respondents (n)
A15: ENG | B15: =COUNTIFS(Responses!$C$6:$C$35,A15,Responses!$AH$6:$AH$35,">0")
A16: HR | B16: =COUNTIFS(Responses!$C$6:$C$35,A16,Responses!$AH$6:$AH$35,">0")
A17: BUD | B17: =COUNTIFS(Responses!$C$6:$C$35,A17,Responses!$AH$6:$AH$35,">0")
A18: ACC | B18: =COUNTIFS(Responses!$C$6:$C$35,A18,Responses!$AH$6:$AH$35,">0")
A19: TRE | B19: =COUNTIFS(Responses!$C$6:$C$35,A19,Responses!$AH$6:$AH$35,">0")
A20: MAY | B20: =COUNTIFS(Responses!$C$6:$C$35,A20,Responses!$AH$6:$AH$35,">0")
A21: Other | B21: =COUNTIFS(Responses!$C$6:$C$35,A21,Responses!$AH$6:$AH$35,">0")
A22: Office not selected | B22: =B11-SUM(B15:B21)
A24: Table 5.3: Verbal interpretation scale
A25: From | B25: To | C25: Interpretation
A26: 1 | B26: 1.8 | C26: Strongly Disagree
A27: 1.81 | B27: 2.6 | C27: Disagree
A28: 2.61 | B28: 3.4 | C28: Uncertain
A29: 3.41 | B29: 4.2 | C29: Agree
A30: 4.21 | B30: 5 | C30: Strongly Agree
A31: Source: Chapter 5 Table 5.3 (verbal scale approved by the research adviser). Change these cells only if the adviser changes the scale.
A33: Table 5.4: ISO/IEC 25010 evaluation results
A34: Characteristic | B34: Items | C34: Answers counted | D34: Weighted mean (WM) | E34: Verbal interpretation
A35: Functional suitability | B35: 4 | C35: =COUNT(Responses!$G$6:$J$35) | D35: =IFERROR(AVERAGE(Responses!$G$6:$J$35),"") | E35: =IF(D35="","",INDEX($C$26:$C$30,MATCH(D35,$A$26:$A$30,1)))
A36: Performance efficiency | B36: 3 | C36: =COUNT(Responses!$K$6:$M$35) | D36: =IFERROR(AVERAGE(Responses!$K$6:$M$35),"") | E36: =IF(D36="","",INDEX($C$26:$C$30,MATCH(D36,$A$26:$A$30,1)))
A37: Compatibility | B37: 3 | C37: =COUNT(Responses!$N$6:$P$35) | D37: =IFERROR(AVERAGE(Responses!$N$6:$P$35),"") | E37: =IF(D37="","",INDEX($C$26:$C$30,MATCH(D37,$A$26:$A$30,1)))
A38: Usability | B38: 4 | C38: =COUNT(Responses!$Q$6:$T$35) | D38: =IFERROR(AVERAGE(Responses!$Q$6:$T$35),"") | E38: =IF(D38="","",INDEX($C$26:$C$30,MATCH(D38,$A$26:$A$30,1)))
A39: Reliability | B39: 3 | C39: =COUNT(Responses!$U$6:$W$35) | D39: =IFERROR(AVERAGE(Responses!$U$6:$W$35),"") | E39: =IF(D39="","",INDEX($C$26:$C$30,MATCH(D39,$A$26:$A$30,1)))
A40: Security | B40: 4 | C40: =COUNT(Responses!$X$6:$AA$35) | D40: =IFERROR(AVERAGE(Responses!$X$6:$AA$35),"") | E40: =IF(D40="","",INDEX($C$26:$C$30,MATCH(D40,$A$26:$A$30,1)))
A41: Maintainability | B41: 3 | C41: =COUNT(Responses!$AB$6:$AD$35) | D41: =IFERROR(AVERAGE(Responses!$AB$6:$AD$35),"") | E41: =IF(D41="","",INDEX($C$26:$C$30,MATCH(D41,$A$26:$A$30,1)))
A42: Portability | B42: 3 | C42: =COUNT(Responses!$AE$6:$AG$35) | D42: =IFERROR(AVERAGE(Responses!$AE$6:$AG$35),"") | E42: =IF(D42="","",INDEX($C$26:$C$30,MATCH(D42,$A$26:$A$30,1)))
A43: Overall WM: mean of the 8 characteristic WMs | D43: =IFERROR(AVERAGE(D35:D42),"") | E43: =IF(D43="","",INDEX($C$26:$C$30,MATCH(D43,$A$26:$A$30,1)))
A44: Overall WM: mean of all item answers | C44: =COUNT(Responses!$G$6:$AG$35) | D44: =IFERROR(AVERAGE(Responses!$G$6:$AG$35),"") | E44: =IF(D44="","",INDEX($C$26:$C$30,MATCH(D44,$A$26:$A$30,1)))
...

Sheet Item_Results
A1: SmartFlow UAT: results per questionnaire item
A2: Formulas only. Use these means in the Chapter 5 discussion of strengths and weaknesses.
A4: Code | B4: Characteristic | C4: Statement | D4: Answers counted | E4: Mean | F4: Verbal interpretation
A5: FS1 | B5: Functional suitability | C5: SmartFlow provides the functions I need to track or monitor document folders in my office. | D5: =COUNT(Responses!$G$6:$G$35) | E5: =IFERROR(AVERAGE(Responses!$G$6:$G$35),"") | F5: =IF(E5="","",INDEX(Summary!$C$26:$C$30,MATCH(E5,Summary!$A$26:$A$30,1)))
A6: FS2 | B6: Functional suitability | C6: Registering a document and getting a QR / tracking ID works as expected. | D6: =COUNT(Responses!$H$6:$H$35) | E6: =IFERROR(AVERAGE(Responses!$H$6:$H$35),"") | F6: =IF(E6="","",INDEX(Summary!$C$26:$C$30,MATCH(E6,Summary!$A$26:$A$30,1)))
A7: FS3 | B7: Functional suitability | C7: Scanning receive (IN) and forward (OUT) records the handoff correctly. | D7: =COUNT(Responses!$I$6:$I$35) | E7: =IFERROR(AVERAGE(Responses!$I$6:$I$35),"") | F7: =IF(E7="","",INDEX(Summary!$C$26:$C$30,MATCH(E7,Summary!$A$26:$A$30,1)))
A8: FS4 | B8: Functional suitability | C8: Dashboards / lists show where documents are and which ones need attention. | D8: =COUNT(Responses!$J$6:$J$35) | E8: =IFERROR(AVERAGE(Responses!$J$6:$J$35),"") | F8: =IF(E8="","",INDEX(Summary!$C$26:$C$30,MATCH(E8,Summary!$A$26:$A$30,1)))
A9: PE1 | B9: Performance efficiency | C9: The system responds quickly enough for daily office use. | D9: =COUNT(Responses!$K$6:$K$35) | E9: =IFERROR(AVERAGE(Responses!$K$6:$K$35),"") | F9: =IF(E9="","",INDEX(Summary!$C$26:$C$30,MATCH(E9,Summary!$A$26:$A$30,1)))
A10: PE2 | B10: Performance efficiency | C10: Login, register, and scan screens load without long delays on our network. | D10: =COUNT(Responses!$L$6:$L$35) | E10: =IFERROR(AVERAGE(Responses!$L$6:$L$35),"") | F10: =IF(E10="","",INDEX(Summary!$C$26:$C$30,MATCH(E10,Summary!$A$26:$A$30,1)))
A11: PE3 | B11: Performance efficiency | C11: Completing a handoff (scan) takes less time than calling or walking to ask for status. | D11: =COUNT(Responses!$M$6:$M$35) | E11: =IFERROR(AVERAGE(Responses!$M$6:$M$35),"") | F11: =IF(E11="","",INDEX(Summary!$C$26:$C$30,MATCH(E11,Summary!$A$26:$A$30,1)))
A12: CO1 | B12: Compatibility | C12: SmartFlow works with the devices we used (browser and/or Android phone). | D12: =COUNT(Responses!$N$6:$N$35) | E12: =IFERROR(AVERAGE(Responses!$N$6:$N$35),"") | F12: =IF(E12="","",INDEX(Summary!$C$26:$C$30,MATCH(E12,Summary!$A$26:$A$30,1)))
A13: CO2 | B13: Compatibility | C13: Using SmartFlow fits our existing practice of moving physical folders between offices. | D13: =COUNT(Responses!$O$6:$O$35) | E13: =IFERROR(AVERAGE(Responses!$O$6:$O$35),"") | F13: =IF(E13="","",INDEX(Summary!$C$26:$C$30,MATCH(E13,Summary!$A$26:$A$30,1)))
A14: CO3 | B14: Compatibility | C14: Web and mobile views are consistent enough that I can understand status either way. | D14: =COUNT(Responses!$P$6:$P$35) | E14: =IFERROR(AVERAGE(Responses!$P$6:$P$35),"") | F14: =IF(E14="","",INDEX(Summary!$C$26:$C$30,MATCH(E14,Summary!$A$26:$A$30,1)))
A15: US1 | B15: Usability | C15: I can learn the main screens with brief training. | D15: =COUNT(Responses!$Q$6:$Q$35) | E15: =IFERROR(AVERAGE(Responses!$Q$6:$Q$35),"") | F15: =IF(E15="","",INDEX(Summary!$C$26:$C$30,MATCH(E15,Summary!$A$26:$A$30,1)))
A16: US2 | B16: Usability | C16: Labels and buttons (Scan, Register, Requests, Alerts) are clear. | D16: =COUNT(Responses!$R$6:$R$35) | E16: =IFERROR(AVERAGE(Responses!$R$6:$R$35),"") | F16: =IF(E16="","",INDEX(Summary!$C$26:$C$30,MATCH(E16,Summary!$A$26:$A$30,1)))
A17: US3 | B17: Usability | C17: Error messages (e.g. wrong scan / duplicate) are understandable. | D17: =COUNT(Responses!$S$6:$S$35) | E17: =IFERROR(AVERAGE(Responses!$S$6:$S$35),"") | F17: =IF(E17="","",INDEX(Summary!$C$26:$C$30,MATCH(E17,Summary!$A$26:$A$30,1)))
A18: US4 | B18: Usability | C18: I can tell the difference between requesting a file and registering a folder on my desk. | D18: =COUNT(Responses!$T$6:$T$35) | E18: =IFERROR(AVERAGE(Responses!$T$6:$T$35),"") | F18: =IF(E18="","",INDEX(Summary!$C$26:$C$30,MATCH(E18,Summary!$A$26:$A$30,1)))
A19: RE1 | B19: Reliability | C19: During the pilot session, SmartFlow worked without frequent crashes or freezes. | D19: =COUNT(Responses!$U$6:$U$35) | E19: =IFERROR(AVERAGE(Responses!$U$6:$U$35),"") | F19: =IF(E19="","",INDEX(Summary!$C$26:$C$30,MATCH(E19,Summary!$A$26:$A$30,1)))
A20: RE2 | B20: Reliability | C20: Document history / trail matched the scans we performed. | D20: =COUNT(Responses!$V$6:$V$35) | E20: =IFERROR(AVERAGE(Responses!$V$6:$V$35),"") | F20: =IF(E20="","",INDEX(Summary!$C$26:$C$30,MATCH(E20,Summary!$A$26:$A$30,1)))
A21: RE3 | B21: Reliability | C21: Rejected illegal actions (e.g. duplicate IN) behave consistently. | D21: =COUNT(Responses!$W$6:$W$35) | E21: =IFERROR(AVERAGE(Responses!$W$6:$W$35),"") | F21: =IF(E21="","",INDEX(Summary!$C$26:$C$30,MATCH(E21,Summary!$A$26:$A$30,1)))
A22: SE1 | B22: Security | C22: Login is required before I can use office functions. | D22: =COUNT(Responses!$X$6:$X$35) | E22: =IFERROR(AVERAGE(Responses!$X$6:$X$35),"") | F22: =IF(E22="","",INDEX(Summary!$C$26:$C$30,MATCH(E22,Summary!$A$26:$A$30,1)))
A23: SE2 | B23: Security | C23: I only see information appropriate to my role / office (as far as I can tell). | D23: =COUNT(Responses!$Y$6:$Y$35) | E23: =IFERROR(AVERAGE(Responses!$Y$6:$Y$35),"") | F23: =IF(E23="","",INDEX(Summary!$C$26:$C$30,MATCH(E23,Summary!$A$26:$A$30,1)))
A24: SE3 | B24: Security | C24: Logging out ends my session on this device. | D24: =COUNT(Responses!$Z$6:$Z$35) | E24: =IFERROR(AVERAGE(Responses!$Z$6:$Z$35),"") | F24: =IF(E24="","",INDEX(Summary!$C$26:$C$30,MATCH(E24,Summary!$A$26:$A$30,1)))
A25: SE4 | B25: Security | C25: I understand SmartFlow tracks folder movement; it does not store the full document content or approve payments. | D25: =COUNT(Responses!$AA$6:$AA$35) | E25: =IFERROR(AVERAGE(Responses!$AA$6:$AA$35),"") | F25: =IF(E25="","",INDEX(Summary!$C$26:$C$30,MATCH(E25,Summary!$A$26:$A$30,1)))
A26: MA1 | B26: Maintainability | C26: Account / profile and password options are reachable when I need them. | D26: =COUNT(Responses!$AB$6:$AB$35) | E26: =IFERROR(AVERAGE(Responses!$AB$6:$AB$35),"") | F26: =IF(E26="","",INDEX(Summary!$C$26:$C$30,MATCH(E26,Summary!$A$26:$A$30,1)))
A27: MA2 | B27: Maintainability | C27: Admin / accountant tools (users, reports, thresholds, QR monitor) look organized enough for pilot use. | D27: =COUNT(Responses!$AC$6:$AC$35) | E27: =IFERROR(AVERAGE(Responses!$AC$6:$AC$35),"") | F27: =IF(E27="","",INDEX(Summary!$C$26:$C$30,MATCH(E27,Summary!$A$26:$A$30,1)))
A28: MA3 | B28: Maintainability | C28: Problems during the demo could be explained or corrected by the research team without rewriting the whole workflow. | D28: =COUNT(Responses!$AD$6:$AD$35) | E28: =IFERROR(AVERAGE(Responses!$AD$6:$AD$35),"") | F28: =IF(E28="","",INDEX(Summary!$C$26:$C$30,MATCH(E28,Summary!$A$26:$A$30,1)))
A29: PO1 | B29: Portability | C29: I can use SmartFlow on the office computer (web) assigned to our unit. | D29: =COUNT(Responses!$AE$6:$AE$35) | E29: =IFERROR(AVERAGE(Responses!$AE$6:$AE$35),"") | F29: =IF(E29="","",INDEX(Summary!$C$26:$C$30,MATCH(E29,Summary!$A$26:$A$30,1)))
A30: PO2 | B30: Portability | C30: I can use SmartFlow on an Android phone for scanning (or I saw a colleague do so successfully). | D30: =COUNT(Responses!$AF$6:$AF$35) | E30: =IFERROR(AVERAGE(Responses!$AF$6:$AF$35),"") | F30: =IF(E30="","",INDEX(Summary!$C$26:$C$30,MATCH(E30,Summary!$A$26:$A$30,1)))
A31: PO3 | B31: Portability | C31: Moving between offices / devices still makes sense for tracking the same folder. | D31: =COUNT(Responses!$AG$6:$AG$35) | E31: =IFERROR(AVERAGE(Responses!$AG$6:$AG$35),"") | F31: =IF(E31="","",INDEX(Summary!$C$26:$C$30,MATCH(E31,Summary!$A$26:$A$30,1)))
