Workbook

Sheet Read me
A1: SmartFlow UAT results tracker
A2: Type the results from each tester's booklet here. The grey cells calculate by themselves.
A4: How to use it
A5: 1 | B5: Give every tester a code (Staff S-01 to S-10, Head H-01 to H-10, Admin A-01 to A-10). Write the code on the booklet.
A6: 2 | B6: Role sheets (Staff, Head, Admin): type Pass, Partial, Fail or N/A for each task, the minutes it took and the hints you gave.
A7: 3 | B7: SUS: type the 10 answers (1 to 5) exactly as ticked. The score is worked out for you. Usefulness: type the 5 ratings (1 to 5).
A8: 4 | B8: Issues: add one row for every problem found, with its severity and later its status.
A9: 5 | B9: Summary: read the pass rates, SUS, open problems and whether the exit criteria are met. Do not type on this sheet.
A10: Colours
A11: Yellow cell, blue text | B11: Type here.
A12: Grey cell | B12: Calculated. Do not type here.
A13: Definitions
A14: Pass rate | B14: Pass divided by (Pass + Partial + Fail). N/A is left out. A Partial result does not count as a pass.
A15: Key task | B15: A task marked with a star (★) in the booklet. The key-task pass rate averages these tasks only.
A16: SUS score | B16: For odd statements the answer minus 1, for even statements 5 minus the answer, added up and multiplied by 2.5 (0 to 100). 68 is the usual average.
A17: Unresolved problem | B17: Any problem whose status is not Fixed or Won't fix (an empty status counts as unresolved).
A19: Example (shows the format only; do not copy into the sheets)
A20: Where | B20: Example entry
A21: Staff sheet, S3, tester S-01 | B21: Pass
A22: Staff sheet, minutes for S3, tester S-01 | B22: 4
A23: SUS sheet, tester S-01 | B23: Role = Staff, answers 4 2 4 1 4 2 5 1 4 2 -> score 82.5
A24: Issues sheet | B24: S-01 | Staff | S5 | Documents | The Send button was hard to find | Major | Open

Sheet Staff
A1: Staff results
A2: Result per task, then minutes, then hints given. Yellow cells are for typing.
A4: Key task | B4: ★ | C4: ★ | D4: ★ | F4: ★ | G4: ★ | H4: ★ | K4: ★ | M4: ★
A5: Tester code | B5: S1 | C5: S2 | D5: S3 | E5: S4 | F5: S5 | G5: S6 | H5: S7 | I5: S8 | J5: S9 | K5: S10 | L5: S11 | M5: S12 | N5: S13 | O5: S14 | P5: S15
A6: S-01
A7: S-02
A8: S-03
A9: S-04
A10: S-05
A11: S-06
A12: S-07
A13: S-08
A14: S-09
A15: S-10
A17: Pass | B17: =COUNTIF(B$6:B$15,"Pass") | C17: =COUNTIF(C$6:C$15,"Pass") | D17: =COUNTIF(D$6:D$15,"Pass") | E17: =COUNTIF(E$6:E$15,"Pass") | F17: =COUNTIF(F$6:F$15,"Pass") | G17: =COUNTIF(G$6:G$15,"Pass") | H17: =COUNTIF(H$6:H$15,"Pass") | I17: =COUNTIF(I$6:I$15,"Pass") | ... P17: =COUNTIF(P$6:P$15,"Pass")
A18: Partial | B18: =COUNTIF(B$6:B$15,"Partial") | C18: =COUNTIF(C$6:C$15,"Partial") | D18: =COUNTIF(D$6:D$15,"Partial") | E18: =COUNTIF(E$6:E$15,"Partial") | F18: =COUNTIF(F$6:F$15,"Partial") | G18: =COUNTIF(G$6:G$15,"Partial") | H18: =COUNTIF(H$6:H$15,"Partial") | I18: =COUNTIF(I$6:I$15,"Partial") | ... P18: =COUNTIF(P$6:P$15,"Partial")
A19: Fail | B19: =COUNTIF(B$6:B$15,"Fail") | C19: =COUNTIF(C$6:C$15,"Fail") | D19: =COUNTIF(D$6:D$15,"Fail") | E19: =COUNTIF(E$6:E$15,"Fail") | F19: =COUNTIF(F$6:F$15,"Fail") | G19: =COUNTIF(G$6:G$15,"Fail") | H19: =COUNTIF(H$6:H$15,"Fail") | I19: =COUNTIF(I$6:I$15,"Fail") | ... P19: =COUNTIF(P$6:P$15,"Fail")
A20: N/A | B20: =COUNTIF(B$6:B$15,"N/A") | C20: =COUNTIF(C$6:C$15,"N/A") | D20: =COUNTIF(D$6:D$15,"N/A") | E20: =COUNTIF(E$6:E$15,"N/A") | F20: =COUNTIF(F$6:F$15,"N/A") | G20: =COUNTIF(G$6:G$15,"N/A") | H20: =COUNTIF(H$6:H$15,"N/A") | I20: =COUNTIF(I$6:I$15,"N/A") | ... P20: =COUNTIF(P$6:P$15,"N/A")
A21: Pass rate | B21: =IF(SUM(B17:B19)=0,"",B17/SUM(B17:B19)) | C21: =IF(SUM(C17:C19)=0,"",C17/SUM(C17:C19)) | D21: =IF(SUM(D17:D19)=0,"",D17/SUM(D17:D19)) | E21: =IF(SUM(E17:E19)=0,"",E17/SUM(E17:E19)) | F21: =IF(SUM(F17:F19)=0,"",F17/SUM(F17:F19)) | G21: =IF(SUM(G17:G19)=0,"",G17/SUM(G17:G19)) | H21: =IF(SUM(H17:H19)=0,"",H17/SUM(H17:H19)) | I21: =IF(SUM(I17:I19)=0,"",I17/SUM(I17:I19)) | ... P21: =IF(SUM(P17:P19)=0,"",P17/SUM(P17:P19))
A24: Time on task (minutes)
A25: Tester code | B25: S1 | C25: S2 | D25: S3 | E25: S4 | F25: S5 | G25: S6 | H25: S7 | I25: S8 | J25: S9 | K25: S10 | L25: S11 | M25: S12 | N25: S13 | O25: S14 | P25: S15
A26: =A6
A27: =A7
A28: =A8
A29: =A9
A30: =A10
A31: =A11
A32: =A12
A33: =A13
A34: =A14
A35: =A15
A37: Average minutes | B37: =IFERROR(AVERAGE(B26:B35),"") | C37: =IFERROR(AVERAGE(C26:C35),"") | D37: =IFERROR(AVERAGE(D26:D35),"") | E37: =IFERROR(AVERAGE(E26:E35),"") | F37: =IFERROR(AVERAGE(F26:F35),"") | G37: =IFERROR(AVERAGE(G26:G35),"") | H37: =IFERROR(AVERAGE(H26:H35),"") | I37: =IFERROR(AVERAGE(I26:I35),"") | ... P37: =IFERROR(AVERAGE(P26:P35),"")
A40: Hints given (assists)
A41: Tester code | B41: S1 | C41: S2 | D41: S3 | E41: S4 | F41: S5 | G41: S6 | H41: S7 | I41: S8 | J41: S9 | K41: S10 | L41: S11 | M41: S12 | N41: S13 | O41: S14 | P41: S15
A42: =A6
A43: =A7
A44: =A8
A45: =A9
A46: =A10
A47: =A11
...

Sheet Head
A1: Head results
A2: Result per task, then minutes, then hints given. Yellow cells are for typing.
A4: Key task | B4: ★ | C4: ★ | G4: ★ | H4: ★
A5: Tester code | B5: H1 | C5: H2 | D5: H3 | E5: H4 | F5: H5 | G5: H6 | H5: H7 | I5: H8 | J5: H9 | K5: H10
A6: H-01
A7: H-02
A8: H-03
A9: H-04
A10: H-05
A11: H-06
A12: H-07
A13: H-08
A14: H-09
A15: H-10
A17: Pass | B17: =COUNTIF(B$6:B$15,"Pass") | C17: =COUNTIF(C$6:C$15,"Pass") | D17: =COUNTIF(D$6:D$15,"Pass") | E17: =COUNTIF(E$6:E$15,"Pass") | F17: =COUNTIF(F$6:F$15,"Pass") | G17: =COUNTIF(G$6:G$15,"Pass") | H17: =COUNTIF(H$6:H$15,"Pass") | I17: =COUNTIF(I$6:I$15,"Pass") | ... K17: =COUNTIF(K$6:K$15,"Pass")
A18: Partial | B18: =COUNTIF(B$6:B$15,"Partial") | C18: =COUNTIF(C$6:C$15,"Partial") | D18: =COUNTIF(D$6:D$15,"Partial") | E18: =COUNTIF(E$6:E$15,"Partial") | F18: =COUNTIF(F$6:F$15,"Partial") | G18: =COUNTIF(G$6:G$15,"Partial") | H18: =COUNTIF(H$6:H$15,"Partial") | I18: =COUNTIF(I$6:I$15,"Partial") | ... K18: =COUNTIF(K$6:K$15,"Partial")
A19: Fail | B19: =COUNTIF(B$6:B$15,"Fail") | C19: =COUNTIF(C$6:C$15,"Fail") | D19: =COUNTIF(D$6:D$15,"Fail") | E19: =COUNTIF(E$6:E$15,"Fail") | F19: =COUNTIF(F$6:F$15,"Fail") | G19: =COUNTIF(G$6:G$15,"Fail") | H19: =COUNTIF(H$6:H$15,"Fail") | I19: =COUNTIF(I$6:I$15,"Fail") | ... K19: =COUNTIF(K$6:K$15,"Fail")
A20: N/A | B20: =COUNTIF(B$6:B$15,"N/A") | C20: =COUNTIF(C$6:C$15,"N/A") | D20: =COUNTIF(D$6:D$15,"N/A") | E20: =COUNTIF(E$6:E$15,"N/A") | F20: =COUNTIF(F$6:F$15,"N/A") | G20: =COUNTIF(G$6:G$15,"N/A") | H20: =COUNTIF(H$6:H$15,"N/A") | I20: =COUNTIF(I$6:I$15,"N/A") | ... K20: =COUNTIF(K$6:K$15,"N/A")
A21: Pass rate | B21: =IF(SUM(B17:B19)=0,"",B17/SUM(B17:B19)) | C21: =IF(SUM(C17:C19)=0,"",C17/SUM(C17:C19)) | D21: =IF(SUM(D17:D19)=0,"",D17/SUM(D17:D19)) | E21: =IF(SUM(E17:E19)=0,"",E17/SUM(E17:E19)) | F21: =IF(SUM(F17:F19)=0,"",F17/SUM(F17:F19)) | G21: =IF(SUM(G17:G19)=0,"",G17/SUM(G17:G19)) | H21: =IF(SUM(H17:H19)=0,"",H17/SUM(H17:H19)) | I21: =IF(SUM(I17:I19)=0,"",I17/SUM(I17:I19)) | ... K21: =IF(SUM(K17:K19)=0,"",K17/SUM(K17:K19))
A24: Time on task (minutes)
A25: Tester code | B25: H1 | C25: H2 | D25: H3 | E25: H4 | F25: H5 | G25: H6 | H25: H7 | I25: H8 | J25: H9 | K25: H10
A26: =A6
A27: =A7
A28: =A8
A29: =A9
A30: =A10
A31: =A11
A32: =A12
A33: =A13
A34: =A14
A35: =A15
A37: Average minutes | B37: =IFERROR(AVERAGE(B26:B35),"") | C37: =IFERROR(AVERAGE(C26:C35),"") | D37: =IFERROR(AVERAGE(D26:D35),"") | E37: =IFERROR(AVERAGE(E26:E35),"") | F37: =IFERROR(AVERAGE(F26:F35),"") | G37: =IFERROR(AVERAGE(G26:G35),"") | H37: =IFERROR(AVERAGE(H26:H35),"") | I37: =IFERROR(AVERAGE(I26:I35),"") | ... K37: =IFERROR(AVERAGE(K26:K35),"")
A40: Hints given (assists)
A41: Tester code | B41: H1 | C41: H2 | D41: H3 | E41: H4 | F41: H5 | G41: H6 | H41: H7 | I41: H8 | J41: H9 | K41: H10
A42: =A6
A43: =A7
A44: =A8
A45: =A9
A46: =A10
A47: =A11
...

Sheet Admin
A1: Admin results
A2: Result per task, then minutes, then hints given. Yellow cells are for typing.
A4: Key task | B4: ★ | C4: ★ | D4: ★ | G4: ★ | I4: ★
A5: Tester code | B5: A1 | C5: A2 | D5: A3 | E5: A4 | F5: A5 | G5: A6 | H5: A7 | I5: A8 | J5: A9 | K5: A10 | L5: A11
A6: A-01
A7: A-02
A8: A-03
A9: A-04
A10: A-05
A11: A-06
A12: A-07
A13: A-08
A14: A-09
A15: A-10
A17: Pass | B17: =COUNTIF(B$6:B$15,"Pass") | C17: =COUNTIF(C$6:C$15,"Pass") | D17: =COUNTIF(D$6:D$15,"Pass") | E17: =COUNTIF(E$6:E$15,"Pass") | F17: =COUNTIF(F$6:F$15,"Pass") | G17: =COUNTIF(G$6:G$15,"Pass") | H17: =COUNTIF(H$6:H$15,"Pass") | I17: =COUNTIF(I$6:I$15,"Pass") | ... L17: =COUNTIF(L$6:L$15,"Pass")
A18: Partial | B18: =COUNTIF(B$6:B$15,"Partial") | C18: =COUNTIF(C$6:C$15,"Partial") | D18: =COUNTIF(D$6:D$15,"Partial") | E18: =COUNTIF(E$6:E$15,"Partial") | F18: =COUNTIF(F$6:F$15,"Partial") | G18: =COUNTIF(G$6:G$15,"Partial") | H18: =COUNTIF(H$6:H$15,"Partial") | I18: =COUNTIF(I$6:I$15,"Partial") | ... L18: =COUNTIF(L$6:L$15,"Partial")
A19: Fail | B19: =COUNTIF(B$6:B$15,"Fail") | C19: =COUNTIF(C$6:C$15,"Fail") | D19: =COUNTIF(D$6:D$15,"Fail") | E19: =COUNTIF(E$6:E$15,"Fail") | F19: =COUNTIF(F$6:F$15,"Fail") | G19: =COUNTIF(G$6:G$15,"Fail") | H19: =COUNTIF(H$6:H$15,"Fail") | I19: =COUNTIF(I$6:I$15,"Fail") | ... L19: =COUNTIF(L$6:L$15,"Fail")
A20: N/A | B20: =COUNTIF(B$6:B$15,"N/A") | C20: =COUNTIF(C$6:C$15,"N/A") | D20: =COUNTIF(D$6:D$15,"N/A") | E20: =COUNTIF(E$6:E$15,"N/A") | F20: =COUNTIF(F$6:F$15,"N/A") | G20: =COUNTIF(G$6:G$15,"N/A") | H20: =COUNTIF(H$6:H$15,"N/A") | I20: =COUNTIF(I$6:I$15,"N/A") | ... L20: =COUNTIF(L$6:L$15,"N/A")
A21: Pass rate | B21: =IF(SUM(B17:B19)=0,"",B17/SUM(B17:B19)) | C21: =IF(SUM(C17:C19)=0,"",C17/SUM(C17:C19)) | D21: =IF(SUM(D17:D19)=0,"",D17/SUM(D17:D19)) | E21: =IF(SUM(E17:E19)=0,"",E17/SUM(E17:E19)) | F21: =IF(SUM(F17:F19)=0,"",F17/SUM(F17:F19)) | G21: =IF(SUM(G17:G19)=0,"",G17/SUM(G17:G19)) | H21: =IF(SUM(H17:H19)=0,"",H17/SUM(H17:H19)) | I21: =IF(SUM(I17:I19)=0,"",I17/SUM(I17:I19)) | ... L21: =IF(SUM(L17:L19)=0,"",L17/SUM(L17:L19))
A24: Time on task (minutes)
A25: Tester code | B25: A1 | C25: A2 | D25: A3 | E25: A4 | F25: A5 | G25: A6 | H25: A7 | I25: A8 | J25: A9 | K25: A10 | L25: A11
A26: =A6
A27: =A7
A28: =A8
A29: =A9
A30: =A10
A31: =A11
A32: =A12
A33: =A13
A34: =A14
A35: =A15
A37: Average minutes | B37: =IFERROR(AVERAGE(B26:B35),"") | C37: =IFERROR(AVERAGE(C26:C35),"") | D37: =IFERROR(AVERAGE(D26:D35),"") | E37: =IFERROR(AVERAGE(E26:E35),"") | F37: =IFERROR(AVERAGE(F26:F35),"") | G37: =IFERROR(AVERAGE(G26:G35),"") | H37: =IFERROR(AVERAGE(H26:H35),"") | I37: =IFERROR(AVERAGE(I26:I35),"") | ... L37: =IFERROR(AVERAGE(L26:L35),"")
A40: Hints given (assists)
A41: Tester code | B41: A1 | C41: A2 | D41: A3 | E41: A4 | F41: A5 | G41: A6 | H41: A7 | I41: A8 | J41: A9 | K41: A10 | L41: A11
A42: =A6
A43: =A7
A44: =A8
A45: =A9
A46: =A10
A47: =A11
...

Sheet SUS
A1: System Usability Scale
A2: Type the answers 1 to 5 as ticked in Part B. Odd statements are worded positively, even statements negatively; the score handles that.
A4: Tester code | B4: Role | C4: Q1 | D4: Q2 | E4: Q3 | F4: Q4 | G4: Q5 | H4: Q6 | I4: Q7 | J4: Q8 | K4: Q9 | L4: Q10 | M4: SUS score
M5: =IF(COUNT(C5:L5)=10,((C5-1)+(5-D5)+(E5-1)+(5-F5)+(G5-1)+(5-H5)+(I5-1)+(5-J5)+(K5-1)+(5-L5))*2.5,"")
M6: =IF(COUNT(C6:L6)=10,((C6-1)+(5-D6)+(E6-1)+(5-F6)+(G6-1)+(5-H6)+(I6-1)+(5-J6)+(K6-1)+(5-L6))*2.5,"")
M7: =IF(COUNT(C7:L7)=10,((C7-1)+(5-D7)+(E7-1)+(5-F7)+(G7-1)+(5-H7)+(I7-1)+(5-J7)+(K7-1)+(5-L7))*2.5,"")
M8: =IF(COUNT(C8:L8)=10,((C8-1)+(5-D8)+(E8-1)+(5-F8)+(G8-1)+(5-H8)+(I8-1)+(5-J8)+(K8-1)+(5-L8))*2.5,"")
M9: =IF(COUNT(C9:L9)=10,((C9-1)+(5-D9)+(E9-1)+(5-F9)+(G9-1)+(5-H9)+(I9-1)+(5-J9)+(K9-1)+(5-L9))*2.5,"")
M10: =IF(COUNT(C10:L10)=10,((C10-1)+(5-D10)+(E10-1)+(5-F10)+(G10-1)+(5-H10)+(I10-1)+(5-J10)+(K10-1)+(5-L10))*2.5,"")
M11: =IF(COUNT(C11:L11)=10,((C11-1)+(5-D11)+(E11-1)+(5-F11)+(G11-1)+(5-H11)+(I11-1)+(5-J11)+(K11-1)+(5-L11))*2.5,"")
M12: =IF(COUNT(C12:L12)=10,((C12-1)+(5-D12)+(E12-1)+(5-F12)+(G12-1)+(5-H12)+(I12-1)+(5-J12)+(K12-1)+(5-L12))*2.5,"")
M13: =IF(COUNT(C13:L13)=10,((C13-1)+(5-D13)+(E13-1)+(5-F13)+(G13-1)+(5-H13)+(I13-1)+(5-J13)+(K13-1)+(5-L13))*2.5,"")
M14: =IF(COUNT(C14:L14)=10,((C14-1)+(5-D14)+(E14-1)+(5-F14)+(G14-1)+(5-H14)+(I14-1)+(5-J14)+(K14-1)+(5-L14))*2.5,"")
M15: =IF(COUNT(C15:L15)=10,((C15-1)+(5-D15)+(E15-1)+(5-F15)+(G15-1)+(5-H15)+(I15-1)+(5-J15)+(K15-1)+(5-L15))*2.5,"")
M16: =IF(COUNT(C16:L16)=10,((C16-1)+(5-D16)+(E16-1)+(5-F16)+(G16-1)+(5-H16)+(I16-1)+(5-J16)+(K16-1)+(5-L16))*2.5,"")
... M34: =IF(COUNT(C34:L34)=10,((C34-1)+(5-D34)+(E34-1)+(5-F34)+(G34-1)+(5-H34)+(I34-1)+(5-J34)+(K34-1)+(5-L34))*2.5,"")
A36: Average SUS
A37: All testers | B37: =IFERROR(AVERAGE(M5:M34),"no data yet") | C37: =IF(ISNUMBER(B37),IF(B37>=80,"Excellent",IF(B37>=68,"Good",IF(B37>=51,"Below average","Poor"))),"")
A38: Staff | B38: =IFERROR(AVERAGEIFS(M5:M34,B5:B34,"Staff"),"no data yet") | C38: =IF(ISNUMBER(B38),IF(B38>=80,"Excellent",IF(B38>=68,"Good",IF(B38>=51,"Below average","Poor"))),"")
A39: Head | B39: =IFERROR(AVERAGEIFS(M5:M34,B5:B34,"Head"),"no data yet") | C39: =IF(ISNUMBER(B39),IF(B39>=80,"Excellent",IF(B39>=68,"Good",IF(B39>=51,"Below average","Poor"))),"")
A40: Admin | B40: =IFERROR(AVERAGEIFS(M5:M34,B5:B34,"Admin"),"no data yet") | C40: =IF(ISNUMBER(B40),IF(B40>=80,"Excellent",IF(B40>=68,"Good",IF(B40>=51,"Below average","Poor"))),"")
A41: Testers scored | B41: =COUNT(M5:M34)

Sheet Usefulness
A1: Usefulness ratings (Part C)
A2: Type the five ratings, 1 (strongly disagree) to 5 (strongly agree).
A4: Tester code | B4: Role | C4: U1 | D4: U2 | E4: U3 | F4: U4 | G4: U5
A36: Average rating
A37: All testers | C37: =IFERROR(AVERAGE(C5:C34),"") | D37: =IFERROR(AVERAGE(D5:D34),"") | E37: =IFERROR(AVERAGE(E5:E34),"") | F37: =IFERROR(AVERAGE(F5:F34),"") | G37: =IFERROR(AVERAGE(G5:G34),"")
A38: Staff | C38: =IFERROR(AVERAGEIFS(C5:C34,$B5:$B34,"Staff"),"") | D38: =IFERROR(AVERAGEIFS(D5:D34,$B5:$B34,"Staff"),"") | E38: =IFERROR(AVERAGEIFS(E5:E34,$B5:$B34,"Staff"),"") | F38: =IFERROR(AVERAGEIFS(F5:F34,$B5:$B34,"Staff"),"") | G38: =IFERROR(AVERAGEIFS(G5:G34,$B5:$B34,"Staff"),"")
A39: Head | C39: =IFERROR(AVERAGEIFS(C5:C34,$B5:$B34,"Head"),"") | D39: =IFERROR(AVERAGEIFS(D5:D34,$B5:$B34,"Head"),"") | E39: =IFERROR(AVERAGEIFS(E5:E34,$B5:$B34,"Head"),"") | F39: =IFERROR(AVERAGEIFS(F5:F34,$B5:$B34,"Head"),"") | G39: =IFERROR(AVERAGEIFS(G5:G34,$B5:$B34,"Head"),"")
A40: Admin | C40: =IFERROR(AVERAGEIFS(C5:C34,$B5:$B34,"Admin"),"") | D40: =IFERROR(AVERAGEIFS(D5:D34,$B5:$B34,"Admin"),"") | E40: =IFERROR(AVERAGEIFS(E5:E34,$B5:$B34,"Admin"),"") | F40: =IFERROR(AVERAGEIFS(F5:F34,$B5:$B34,"Admin"),"") | G40: =IFERROR(AVERAGEIFS(G5:G34,$B5:$B34,"Admin"),"")
A42: Statements
A43: U1 | B43: Easier to know where a folder is
A44: U2 | B44: Would save time
A45: U3 | B45: Alerts and reports show what needs attention
A46: U4 | B46: I trust the history records
A47: U5 | B47: Would recommend it

Sheet Issues
A1: Problems found
A2: One row per problem. Severity: Blocker, Major, Minor or Suggestion. Status starts as Open.
A4: # | B4: Tester code | C4: Role | D4: Task | E4: Where (page or screen) | F4: What happened | G4: What was expected | H4: Severity | I4: Status | J4: Fix or decision
A5: =IF(F5="","",ROW()-4)
A6: =IF(F6="","",ROW()-4)
A7: =IF(F7="","",ROW()-4)
A8: =IF(F8="","",ROW()-4)
A9: =IF(F9="","",ROW()-4)
A10: =IF(F10="","",ROW()-4)
A11: =IF(F11="","",ROW()-4)
A12: =IF(F12="","",ROW()-4)
A13: =IF(F13="","",ROW()-4)
A14: =IF(F14="","",ROW()-4)
A15: =IF(F15="","",ROW()-4)
A16: =IF(F16="","",ROW()-4)
... A64: =IF(F64="","",ROW()-4)

Sheet Summary
A1: Summary
A2: Calculated from the other sheets. Do not type here.
A4: By role
A5: Measure | B5: Staff | C5: Head | D5: Admin
A6: Testers with a SUS score | B6: =COUNTIFS(SUS!$B$5:$B$34,"Staff",SUS!$M$5:$M$34,">=0") | C6: =COUNTIFS(SUS!$B$5:$B$34,"Head",SUS!$M$5:$M$34,">=0") | D6: =COUNTIFS(SUS!$B$5:$B$34,"Admin",SUS!$M$5:$M$34,">=0")
A7: Key-task pass rate (average of ★ tasks) | B7: =IFERROR(AVERAGEIFS(Staff!B21:P21,Staff!B4:P4,"★"),"no data yet") | C7: =IFERROR(AVERAGEIFS(Head!B21:K21,Head!B4:K4,"★"),"no data yet") | D7: =IFERROR(AVERAGEIFS(Admin!B21:L21,Admin!B4:L4,"★"),"no data yet")
A8: All-task pass rate (average) | B8: =IFERROR(AVERAGE(Staff!B21:P21),"no data yet") | C8: =IFERROR(AVERAGE(Head!B21:K21),"no data yet") | D8: =IFERROR(AVERAGE(Admin!B21:L21),"no data yet")
A9: Average minutes per task | B9: =IFERROR(AVERAGE(Staff!B37:P37),"no data yet") | C9: =IFERROR(AVERAGE(Head!B37:K37),"no data yet") | D9: =IFERROR(AVERAGE(Admin!B37:L37),"no data yet")
A10: Hints given (total) | B10: =SUM(Staff!B53:P53) | C10: =SUM(Head!B53:K53) | D10: =SUM(Admin!B53:L53)
A11: Average SUS score | B11: =IFERROR(AVERAGEIFS(SUS!$M$5:$M$34,SUS!$B$5:$B$34,"Staff"),"no data yet") | C11: =IFERROR(AVERAGEIFS(SUS!$M$5:$M$34,SUS!$B$5:$B$34,"Head"),"no data yet") | D11: =IFERROR(AVERAGEIFS(SUS!$M$5:$M$34,SUS!$B$5:$B$34,"Admin"),"no data yet")
A13: All testers
A14: Measure | B14: Value
A15: Average SUS score | B15: =IFERROR(AVERAGE(SUS!M5:M34),"no data yet") | C15: =IF(ISNUMBER(B15),IF(B15>=80,"Excellent",IF(B15>=68,"Good",IF(B15>=51,"Below average","Poor"))),"")
A16: Usefulness U1: Easier to know where a folder is | B16: =IFERROR(AVERAGE(Usefulness!C5:C34),"no data yet")
A17: Usefulness U2: Would save time | B17: =IFERROR(AVERAGE(Usefulness!D5:D34),"no data yet")
A18: Usefulness U3: Alerts and reports show what needs attention | B18: =IFERROR(AVERAGE(Usefulness!E5:E34),"no data yet")
A19: Usefulness U4: I trust the history records | B19: =IFERROR(AVERAGE(Usefulness!F5:F34),"no data yet")
A20: Usefulness U5: Would recommend it | B20: =IFERROR(AVERAGE(Usefulness!G5:G34),"no data yet")
A22: Problems
A23: Severity | B23: All logged | C23: Unresolved
A24: Blocker | B24: =COUNTIF(Issues!$H$5:$H$64,"Blocker") | C24: =COUNTIFS(Issues!$H$5:$H$64,"Blocker",Issues!$I$5:$I$64,"<>Fixed",Issues!$I$5:$I$64,"<>Won't fix")
A25: Major | B25: =COUNTIF(Issues!$H$5:$H$64,"Major") | C25: =COUNTIFS(Issues!$H$5:$H$64,"Major",Issues!$I$5:$I$64,"<>Fixed",Issues!$I$5:$I$64,"<>Won't fix")
A26: Minor | B26: =COUNTIF(Issues!$H$5:$H$64,"Minor") | C26: =COUNTIFS(Issues!$H$5:$H$64,"Minor",Issues!$I$5:$I$64,"<>Fixed",Issues!$I$5:$I$64,"<>Won't fix")
A27: Suggestion | B27: =COUNTIF(Issues!$H$5:$H$64,"Suggestion") | C27: =COUNTIFS(Issues!$H$5:$H$64,"Suggestion",Issues!$I$5:$I$64,"<>Fixed",Issues!$I$5:$I$64,"<>Won't fix")
A29: Exit criteria (proposed in the Facilitator Guide)
A30: Criterion | B30: Status
A31: 1. Every role: at least 90% of testers pass each key task (★) | B31: =IF(COUNT(B7:D7)<3,"Not enough data",IF(MIN(B7:D7)>=0.9,"Met","Not met"))
A32: 2. No Blocker problem is unresolved | B32: =IF(SUM(B6:D6)=0,"Not enough data",IF(C24=0,"Met","Not met"))
A33: 3. Average SUS score is at least 68 | B33: =IF(ISNUMBER(B15),IF(B15>=68,"Met","Not met"),"Not enough data")
A34: 4. Every Major problem is fixed or has a written decision | B34: =IF(SUM(B6:D6)=0,"Not enough data",IF(C25=0,"Met","Not met"))
